assert.throws(Test262Error, function() {
  try {
    throw [undefined];
  } catch ([x = (function() { throw new Test262Error(); })()]) {}
});